I'm sorry, but an uncaught exception occurred.

While running game code:
  File "game/script.rpy", line 13, in script call
    call s1_start
  File "game/script_s1.rpy", line 14, in script
    char_dad "How you feeling?"
Exception: Sayer 'char_dad' is not defined.

-- Full Traceback ------------------------------------------------------------

Full traceback:
  File "game/script.rpy", line 13, in script call
    call s1_start
  File "game/script_s1.rpy", line 14, in script
    char_dad "How you feeling?"
  File "C:\Users\benta\Desktop\renpy-8.0.3-sdk\renpy\ast.py", line 881, in execute
    who = eval_who(self.who, self.who_fast)
  File "C:\Users\benta\Desktop\renpy-8.0.3-sdk\renpy\ast.py", line 774, in eval_who
    raise Exception("Sayer '%s' is not defined." % who)
Exception: Sayer 'char_dad' is not defined.

Windows-10-10.0.19043 AMD64
Ren'Py 8.0.3.22090809
Diffusion Prototype 1.0
Sun Sep 25 12:19:50 2022
